Workbook

Sheet GF_Import
A1: 📥 GOOGLE FINANCE — OHLCV IMPORT
A2: Data GF_Import diisi otomatis dari idx_scraper.fetch_ohlcv untuk 10 hari terakhir per kode saham input. Jika data tidak tersedia, baris kosong tetap dibuat untuk diisi manual.
A4: KODE | B4: Tanggal | C4: Open | D4: High | E4: Low | F4: Close | G4: Volume | H4: % Change
A5: BBCA | B5: 46175 | C5: 5750 | D5: 5875 | E5: 5700 | F5: 5825 | G5: 346305200 | H5: -
A6: BBCA | B6: 46176 | C6: 5775 | D6: 5825 | E6: 5525 | F6: 5525 | G6: 353332300 | H6: -0.0515
A7: BBCA | B7: 46177 | C7: 5475 | D7: 5600 | E7: 5300 | F7: 5425 | G7: 550059500 | H7: -0.0181
A8: BBCA | B8: 46178 | C8: 5325 | D8: 5375 | E8: 5075 | F8: 5075 | G8: 572612000 | H8: -0.0645
A9: BBCA | B9: 46181 | C9: 4950 | D9: 5050 | E9: 4850 | F9: 4850 | G9: 705093300 | H9: -0.0443
A10: BBCA | B10: 46182 | C10: 4850 | D10: 5150 | E10: 4820 | F10: 5150 | G10: 772898000 | H10: 0.0619
A11: BBCA | B11: 46183 | C11: 5175 | D11: 5700 | E11: 5175 | F11: 5650 | G11: 747366000 | H11: 0.0971
A12: BBCA | B12: 46184 | C12: 5650 | D12: 5875 | E12: 5550 | F12: 5825 | G12: 543032300 | H12: 0.031
A13: BBCA | B13: 46185 | C13: 6000 | D13: 6100 | E13: 5900 | F13: 5925 | G13: 415872300 | H13: 0.0172
A14: BBCA | B14: 46188 | C14: 6100 | D14: 6425 | E14: 6100 | F14: 6275 | G14: 476865200 | H14: 0.0591
A15: BBRI | B15: 46175 | C15: 3000 | D15: 3040 | E15: 2980 | F15: 3040 | G15: 320974000 | H15: -
A16: BBRI | B16: 46176 | C16: 3050 | D16: 3070 | E16: 2900 | F16: 2900 | G16: 411746000 | H16: -0.0461
A17: BBRI | B17: 46177 | C17: 2900 | D17: 2930 | E17: 2780 | F17: 2810 | G17: 493450500 | H17: -0.031
A18: BBRI | B18: 46178 | C18: 2780 | D18: 2830 | E18: 2730 | F18: 2740 | G18: 310053600 | H18: -0.0249
A19: BBRI | B19: 46181 | C19: 2700 | D19: 2750 | E19: 2590 | F19: 2590 | G19: 626878600 | H19: -0.0547
A20: BBRI | B20: 46182 | C20: 2540 | D20: 2800 | E20: 2540 | F20: 2790 | G20: 873192700 | H20: 0.0772
A21: BBRI | B21: 46183 | C21: 2790 | D21: 2910 | E21: 2730 | F21: 2880 | G21: 704423000 | H21: 0.0323
A22: BBRI | B22: 46184 | C22: 2880 | D22: 2960 | E22: 2780 | F22: 2850 | G22: 465509700 | H22: -0.0104
A23: BBRI | B23: 46185 | C23: 2880 | D23: 2900 | E23: 2830 | F23: 2850 | G23: 450530000 | H23: 0
A24: BBRI | B24: 46188 | C24: 2890 | D24: 3050 | E24: 2890 | F24: 2990 | G24: 615861900 | H24: 0.0491
A25: TLKM | B25: 46175 | C25: 2990 | D25: 3020 | E25: 2910 | F25: 2950 | G25: 242446000 | H25: -
A26: TLKM | B26: 46176 | C26: 2900 | D26: 2950 | E26: 2850 | F26: 2850 | G26: 168085400 | H26: -0.0339
A27: TLKM | B27: 46177 | C27: 2900 | D27: 2950 | E27: 2680 | F27: 2900 | G27: 197151900 | H27: 0.0175
A28: TLKM | B28: 46178 | C28: 2900 | D28: 2930 | E28: 2760 | F28: 2760 | G28: 105040300 | H28: -0.0483
A29: TLKM | B29: 46181 | C29: 2620 | D29: 2650 | E29: 2350 | F29: 2350 | G29: 331947700 | H29: -0.1486
A30: TLKM | B30: 46182 | C30: 2510 | D30: 2620 | E30: 2510 | F30: 2620 | G30: 371055600 | H30: 0.1149
A31: TLKM | B31: 46183 | C31: 2500 | D31: 2810 | E31: 2500 | F31: 2810 | G31: 391732600 | H31: 0.0725
A32: TLKM | B32: 46184 | C32: 2870 | D32: 2970 | E32: 2810 | F32: 2870 | G32: 274793100 | H32: 0.0214
A33: TLKM | B33: 46185 | C33: 2910 | D33: 2980 | E33: 2860 | F33: 2860 | G33: 181531900 | H33: -0.0035
A34: TLKM | B34: 46188 | C34: 2900 | D34: 2970 | E34: 2890 | F34: 2930 | G34: 153652900 | H34: 0.0245
A35: DEWA | B35: 46175 | C35: 338 | D35: 352 | E35: 330 | F35: 334 | G35: 429443500 | H35: -
A36: DEWA | B36: 46176 | C36: 338 | D36: 340 | E36: 284 | F36: 294 | G36: 955812900 | H36: -0.1198
A37: DEWA | B37: 46177 | C37: 292 | D37: 302 | E37: 250 | F37: 286 | G37: 1067018200 | H37: -0.0272
A38: DEWA | B38: 46178 | C38: 292 | D38: 294 | E38: 262 | F38: 262 | G38: 654394600 | H38: -0.0839
A39: DEWA | B39: 46181 | C39: 254 | D39: 264 | E39: 234 | F39: 250 | G39: 553025400 | H39: -0.0458
A40: DEWA | B40: 46182 | C40: 250 | D40: 282 | E40: 244 | F40: 280 | G40: 1133523000 | H40: 0.12
A41: DEWA | B41: 46183 | C41: 280 | D41: 324 | E41: 270 | F41: 302 | G41: 1512078300 | H41: 0.0786
...

Sheet Price_Chart
A1: 📊 ANALISIS OHLCV & TEKNIKAL PER SAHAM
A2: Pilih Saham: | B2: BBCA | C2: ← Pilih kode dari dropdown
A4: Kode | B4: Tgl Terakhir | C4: Close | D4: High 10H | E4: Low 10H | F4: Vol | G4: Vol Avg 10H | H4: Vol Mult
A5: =B2 | B5: =IFERROR(MAXIFS(GF_Import!B:B,GF_Import!A:A,B2),"N/A") | C5: =IFERROR(INDEX(GF_Import!F:F,MATCH(B2&MAXIFS(GF_Import!B:B,GF_Import!A:A,B2),GF_Import!A:A&GF_Import!B:B,0)),"N/A") | D5: =IFERROR(MAXIFS(GF_Import!D:D,GF_Import!A:A,B2),"N/A") | E5: =IFERROR(MINIFS(GF_Import!E:E,GF_Import!A:A,B2),"N/A") | F5: =IFERROR(SUMIF(GF_Import!A:A,B2,GF_Import!G:G)/COUNTIF(GF_Import!A:A,B2),"N/A") | G5: =IFERROR(SUMIF(GF_Import!A:A,B2,GF_Import!G:G)/COUNTIF(GF_Import!A:A,B2),"N/A") | H5: =IFERROR(C5/G5,"N/A")
A7: Data Chart (auto-filter dari GF_Import untuk saham terpilih):
A8: No | B8: Tanggal | C8: Open | D8: High | E8: Low | F8: Close | G8: Volume | H8: MA 20 | I8: % Chg
A9: 1 | B9: =IFERROR(INDEX(GF_Import!B:B,MATCH(AGGREGATE(15,6,(ROW(GF_Import!A$5:A$500)-ROW(GF_Import!A$5)+1)/(GF_Import!A$5:A$500=$B$2),1)+ROW(GF_Import!A$5)-1,ROW(GF_Import!A$5:A$500)-ROW(GF_Import!A$5)+1+ROW(GF_Import!A$5)-1,0)),"") | C9: =IFERROR(INDEX(GF_Import!C:C,MATCH(AGGREGATE(15,6,(ROW(GF_Import!A$5:A$500)-ROW(GF_Import!A$5)+1)/(GF_Import!A$5:A$500=$B$2),1)+ROW(GF_Import!A$5)-1,ROW(GF_Import!A$5:A$500)-ROW(GF_Import!A$5)+1+ROW(GF_Import!A$5)-1,0)),"") | D9: =IFERROR(INDEX(GF_Import!D:D,MATCH(AGGREGATE(15,6,(ROW(GF_Import!A$5:A$500)-ROW(GF_Import!A$5)+1)/(GF_Import!A$5:A$500=$B$2),1)+ROW(GF_Import!A$5)-1,ROW(GF_Import!A$5:A$500)-ROW(GF_Import!A$5)+1+ROW(GF_Import!A$5)-1,0)),"") | E9: =IFERROR(INDEX(GF_Import!E:E,MATCH(AGGREGATE(15,6,(ROW(GF_Import!A$5:A$500)-ROW(GF_Import!A$5)+1)/(GF_Import!A$5:A$500=$B$2),1)+ROW(GF_Import!A$5)-1,ROW(GF_Import!A$5:A$500)-ROW(GF_Import!A$5)+1+ROW(GF_Import!A$5)-1,0)),"") | F9: =IFERROR(INDEX(GF_Import!F:F,MATCH(AGGREGATE(15,6,(ROW(GF_Import!A$5:A$500)-ROW(GF_Import!A$5)+1)/(GF_Import!A$5:A$500=$B$2),1)+ROW(GF_Import!A$5)-1,ROW(GF_Import!A$5:A$500)-ROW(GF_Import!A$5)+1+ROW(GF_Import!A$5)-1,0)),"") | G9: =IFERROR(INDEX(GF_Import!G:G,MATCH(AGGREGATE(15,6,(ROW(GF_Import!A$5:A$500)-ROW(GF_Import!A$5)+1)/(GF_Import!A$5:A$500=$B$2),1)+ROW(GF_Import!A$5)-1,ROW(GF_Import!A$5:A$500)-ROW(GF_Import!A$5)+1+ROW(GF_Import!A$5)-1,0)),"") | H9: =IF(F9="","",IFERROR(AVERAGEIF(GF_Import!A:A,$B$2,GF_Import!F:F),"")) | I9: =IF(OR(F9="",F8=""),"",IFERROR((F9-F8)/F8,""))
A10: 2 | B10: =IFERROR(INDEX(GF_Import!B:B,MATCH(AGGREGATE(15,6,(ROW(GF_Import!A$5:A$500)-ROW(GF_Import!A$5)+1)/(GF_Import!A$5:A$500=$B$2),2)+ROW(GF_Import!A$5)-1,ROW(GF_Import!A$5:A$500)-ROW(GF_Import!A$5)+1+ROW(GF_Import!A$5)-1,0)),"") | C10: =IFERROR(INDEX(GF_Import!C:C,MATCH(AGGREGATE(15,6,(ROW(GF_Import!A$5:A$500)-ROW(GF_Import!A$5)+1)/(GF_Import!A$5:A$500=$B$2),2)+ROW(GF_Import!A$5)-1,ROW(GF_Import!A$5:A$500)-ROW(GF_Import!A$5)+1+ROW(GF_Import!A$5)-1,0)),"") | D10: =IFERROR(INDEX(GF_Import!D:D,MATCH(AGGREGATE(15,6,(ROW(GF_Import!A$5:A$500)-ROW(GF_Import!A$5)+1)/(GF_Import!A$5:A$500=$B$2),2)+ROW(GF_Import!A$5)-1,ROW(GF_Import!A$5:A$500)-ROW(GF_Import!A$5)+1+ROW(GF_Import!A$5)-1,0)),"") | E10: =IFERROR(INDEX(GF_Import!E:E,MATCH(AGGREGATE(15,6,(ROW(GF_Import!A$5:A$500)-ROW(GF_Import!A$5)+1)/(GF_Import!A$5:A$500=$B$2),2)+ROW(GF_Import!A$5)-1,ROW(GF_Import!A$5:A$500)-ROW(GF_Import!A$5)+1+ROW(GF_Import!A$5)-1,0)),"") | F10: =IFERROR(INDEX(GF_Import!F:F,MATCH(AGGREGATE(15,6,(ROW(GF_Import!A$5:A$500)-ROW(GF_Import!A$5)+1)/(GF_Import!A$5:A$500=$B$2),2)+ROW(GF_Import!A$5)-1,ROW(GF_Import!A$5:A$500)-ROW(GF_Import!A$5)+1+ROW(GF_Import!A$5)-1,0)),"") | G10: =IFERROR(INDEX(GF_Import!G:G,MATCH(AGGREGATE(15,6,(ROW(GF_Import!A$5:A$500)-ROW(GF_Import!A$5)+1)/(GF_Import!A$5:A$500=$B$2),2)+ROW(GF_Import!A$5)-1,ROW(GF_Import!A$5:A$500)-ROW(GF_Import!A$5)+1+ROW(GF_Import!A$5)-1,0)),"") | H10: =IF(F10="","",IFERROR(AVERAGEIF(GF_Import!A:A,$B$2,GF_Import!F:F),"")) | I10: =IF(OR(F10="",F9=""),"",IFERROR((F10-F9)/F9,""))
A11: 3 | B11: =IFERROR(INDEX(GF_Import!B:B,MATCH(AGGREGATE(15,6,(ROW(GF_Import!A$5:A$500)-ROW(GF_Import!A$5)+1)/(GF_Import!A$5:A$500=$B$2),3)+ROW(GF_Import!A$5)-1,ROW(GF_Import!A$5:A$500)-ROW(GF_Import!A$5)+1+ROW(GF_Import!A$5)-1,0)),"") | C11: =IFERROR(INDEX(GF_Import!C:C,MATCH(AGGREGATE(15,6,(ROW(GF_Import!A$5:A$500)-ROW(GF_Import!A$5)+1)/(GF_Import!A$5:A$500=$B$2),3)+ROW(GF_Import!A$5)-1,ROW(GF_Import!A$5:A$500)-ROW(GF_Import!A$5)+1+ROW(GF_Import!A$5)-1,0)),"") | D11: =IFERROR(INDEX(GF_Import!D:D,MATCH(AGGREGATE(15,6,(ROW(GF_Import!A$5:A$500)-ROW(GF_Import!A$5)+1)/(GF_Import!A$5:A$500=$B$2),3)+ROW(GF_Import!A$5)-1,ROW(GF_Import!A$5:A$500)-ROW(GF_Import!A$5)+1+ROW(GF_Import!A$5)-1,0)),"") | E11: =IFERROR(INDEX(GF_Import!E:E,MATCH(AGGREGATE(15,6,(ROW(GF_Import!A$5:A$500)-ROW(GF_Import!A$5)+1)/(GF_Import!A$5:A$500=$B$2),3)+ROW(GF_Import!A$5)-1,ROW(GF_Import!A$5:A$500)-ROW(GF_Import!A$5)+1+ROW(GF_Import!A$5)-1,0)),"") | F11: =IFERROR(INDEX(GF_Import!F:F,MATCH(AGGREGATE(15,6,(ROW(GF_Import!A$5:A$500)-ROW(GF_Import!A$5)+1)/(GF_Import!A$5:A$500=$B$2),3)+ROW(GF_Import!A$5)-1,ROW(GF_Import!A$5:A$500)-ROW(GF_Import!A$5)+1+ROW(GF_Import!A$5)-1,0)),"") | G11: =IFERROR(INDEX(GF_Import!G:G,MATCH(AGGREGATE(15,6,(ROW(GF_Import!A$5:A$500)-ROW(GF_Import!A$5)+1)/(GF_Import!A$5:A$500=$B$2),3)+ROW(GF_Import!A$5)-1,ROW(GF_Import!A$5:A$500)-ROW(GF_Import!A$5)+1+ROW(GF_Import!A$5)-1,0)),"") | H11: =IF(F11="","",IFERROR(AVERAGEIF(GF_Import!A:A,$B$2,GF_Import!F:F),"")) | I11: =IF(OR(F11="",F10=""),"",IFERROR((F11-F10)/F10,""))
A12: 4 | B12: =IFERROR(INDEX(GF_Import!B:B,MATCH(AGGREGATE(15,6,(ROW(GF_Import!A$5:A$500)-ROW(GF_Import!A$5)+1)/(GF_Import!A$5:A$500=$B$2),4)+ROW(GF_Import!A$5)-1,ROW(GF_Import!A$5:A$500)-ROW(GF_Import!A$5)+1+ROW(GF_Import!A$5)-1,0)),"") | C12: =IFERROR(INDEX(GF_Import!C:C,MATCH(AGGREGATE(15,6,(ROW(GF_Import!A$5:A$500)-ROW(GF_Import!A$5)+1)/(GF_Import!A$5:A$500=$B$2),4)+ROW(GF_Import!A$5)-1,ROW(GF_Import!A$5:A$500)-ROW(GF_Import!A$5)+1+ROW(GF_Import!A$5)-1,0)),"") | D12: =IFERROR(INDEX(GF_Import!D:D,MATCH(AGGREGATE(15,6,(ROW(GF_Import!A$5:A$500)-ROW(GF_Import!A$5)+1)/(GF_Import!A$5:A$500=$B$2),4)+ROW(GF_Import!A$5)-1,ROW(GF_Import!A$5:A$500)-ROW(GF_Import!A$5)+1+ROW(GF_Import!A$5)-1,0)),"") | E12: =IFERROR(INDEX(GF_Import!E:E,MATCH(AGGREGATE(15,6,(ROW(GF_Import!A$5:A$500)-ROW(GF_Import!A$5)+1)/(GF_Import!A$5:A$500=$B$2),4)+ROW(GF_Import!A$5)-1,ROW(GF_Import!A$5:A$500)-ROW(GF_Import!A$5)+1+ROW(GF_Import!A$5)-1,0)),"") | F12: =IFERROR(INDEX(GF_Import!F:F,MATCH(AGGREGATE(15,6,(ROW(GF_Import!A$5:A$500)-ROW(GF_Import!A$5)+1)/(GF_Import!A$5:A$500=$B$2),4)+ROW(GF_Import!A$5)-1,ROW(GF_Import!A$5:A$500)-ROW(GF_Import!A$5)+1+ROW(GF_Import!A$5)-1,0)),"") | G12: =IFERROR(INDEX(GF_Import!G:G,MATCH(AGGREGATE(15,6,(ROW(GF_Import!A$5:A$500)-ROW(GF_Import!A$5)+1)/(GF_Import!A$5:A$500=$B$2),4)+ROW(GF_Import!A$5)-1,ROW(GF_Import!A$5:A$500)-ROW(GF_Import!A$5)+1+ROW(GF_Import!A$5)-1,0)),"") | H12: =IF(F12="","",IFERROR(AVERAGEIF(GF_Import!A:A,$B$2,GF_Import!F:F),"")) | I12: =IF(OR(F12="",F11=""),"",IFERROR((F12-F11)/F11,""))
A13: 5 | B13: =IFERROR(INDEX(GF_Import!B:B,MATCH(AGGREGATE(15,6,(ROW(GF_Import!A$5:A$500)-ROW(GF_Import!A$5)+1)/(GF_Import!A$5:A$500=$B$2),5)+ROW(GF_Import!A$5)-1,ROW(GF_Import!A$5:A$500)-ROW(GF_Import!A$5)+1+ROW(GF_Import!A$5)-1,0)),"") | C13: =IFERROR(INDEX(GF_Import!C:C,MATCH(AGGREGATE(15,6,(ROW(GF_Import!A$5:A$500)-ROW(GF_Import!A$5)+1)/(GF_Import!A$5:A$500=$B$2),5)+ROW(GF_Import!A$5)-1,ROW(GF_Import!A$5:A$500)-ROW(GF_Import!A$5)+1+ROW(GF_Import!A$5)-1,0)),"") | D13: =IFERROR(INDEX(GF_Import!D:D,MATCH(AGGREGATE(15,6,(ROW(GF_Import!A$5:A$500)-ROW(GF_Import!A$5)+1)/(GF_Import!A$5:A$500=$B$2),5)+ROW(GF_Import!A$5)-1,ROW(GF_Import!A$5:A$500)-ROW(GF_Import!A$5)+1+ROW(GF_Import!A$5)-1,0)),"") | E13: =IFERROR(INDEX(GF_Import!E:E,MATCH(AGGREGATE(15,6,(ROW(GF_Import!A$5:A$500)-ROW(GF_Import!A$5)+1)/(GF_Import!A$5:A$500=$B$2),5)+ROW(GF_Import!A$5)-1,ROW(GF_Import!A$5:A$500)-ROW(GF_Import!A$5)+1+ROW(GF_Import!A$5)-1,0)),"") | F13: =IFERROR(INDEX(GF_Import!F:F,MATCH(AGGREGATE(15,6,(ROW(GF_Import!A$5:A$500)-ROW(GF_Import!A$5)+1)/(GF_Import!A$5:A$500=$B$2),5)+ROW(GF_Import!A$5)-1,ROW(GF_Import!A$5:A$500)-ROW(GF_Import!A$5)+1+ROW(GF_Import!A$5)-1,0)),"") | G13: =IFERROR(INDEX(GF_Import!G:G,MATCH(AGGREGATE(15,6,(ROW(GF_Import!A$5:A$500)-ROW(GF_Import!A$5)+1)/(GF_Import!A$5:A$500=$B$2),5)+ROW(GF_Import!A$5)-1,ROW(GF_Import!A$5:A$500)-ROW(GF_Import!A$5)+1+ROW(GF_Import!A$5)-1,0)),"") | H13: =IF(F13="","",IFERROR(AVERAGEIF(GF_Import!A:A,$B$2,GF_Import!F:F),"")) | I13: =IF(OR(F13="",F12=""),"",IFERROR((F13-F12)/F12,""))
A14: 6 | B14: =IFERROR(INDEX(GF_Import!B:B,MATCH(AGGREGATE(15,6,(ROW(GF_Import!A$5:A$500)-ROW(GF_Import!A$5)+1)/(GF_Import!A$5:A$500=$B$2),6)+ROW(GF_Import!A$5)-1,ROW(GF_Import!A$5:A$500)-ROW(GF_Import!A$5)+1+ROW(GF_Import!A$5)-1,0)),"") | C14: =IFERROR(INDEX(GF_Import!C:C,MATCH(AGGREGATE(15,6,(ROW(GF_Import!A$5:A$500)-ROW(GF_Import!A$5)+1)/(GF_Import!A$5:A$500=$B$2),6)+ROW(GF_Import!A$5)-1,ROW(GF_Import!A$5:A$500)-ROW(GF_Import!A$5)+1+ROW(GF_Import!A$5)-1,0)),"") | D14: =IFERROR(INDEX(GF_Import!D:D,MATCH(AGGREGATE(15,6,(ROW(GF_Import!A$5:A$500)-ROW(GF_Import!A$5)+1)/(GF_Import!A$5:A$500=$B$2),6)+ROW(GF_Import!A$5)-1,ROW(GF_Import!A$5:A$500)-ROW(GF_Import!A$5)+1+ROW(GF_Import!A$5)-1,0)),"") | E14: =IFERROR(INDEX(GF_Import!E:E,MATCH(AGGREGATE(15,6,(ROW(GF_Import!A$5:A$500)-ROW(GF_Import!A$5)+1)/(GF_Import!A$5:A$500=$B$2),6)+ROW(GF_Import!A$5)-1,ROW(GF_Import!A$5:A$500)-ROW(GF_Import!A$5)+1+ROW(GF_Import!A$5)-1,0)),"") | F14: =IFERROR(INDEX(GF_Import!F:F,MATCH(AGGREGATE(15,6,(ROW(GF_Import!A$5:A$500)-ROW(GF_Import!A$5)+1)/(GF_Import!A$5:A$500=$B$2),6)+ROW(GF_Import!A$5)-1,ROW(GF_Import!A$5:A$500)-ROW(GF_Import!A$5)+1+ROW(GF_Import!A$5)-1,0)),"") | G14: =IFERROR(INDEX(GF_Import!G:G,MATCH(AGGREGATE(15,6,(ROW(GF_Import!A$5:A$500)-ROW(GF_Import!A$5)+1)/(GF_Import!A$5:A$500=$B$2),6)+ROW(GF_Import!A$5)-1,ROW(GF_Import!A$5:A$500)-ROW(GF_Import!A$5)+1+ROW(GF_Import!A$5)-1,0)),"") | H14: =IF(F14="","",IFERROR(AVERAGEIF(GF_Import!A:A,$B$2,GF_Import!F:F),"")) | I14: =IF(OR(F14="",F13=""),"",IFERROR((F14-F13)/F13,""))
A15: 7 | B15: =IFERROR(INDEX(GF_Import!B:B,MATCH(AGGREGATE(15,6,(ROW(GF_Import!A$5:A$500)-ROW(GF_Import!A$5)+1)/(GF_Import!A$5:A$500=$B$2),7)+ROW(GF_Import!A$5)-1,ROW(GF_Import!A$5:A$500)-ROW(GF_Import!A$5)+1+ROW(GF_Import!A$5)-1,0)),"") | C15: =IFERROR(INDEX(GF_Import!C:C,MATCH(AGGREGATE(15,6,(ROW(GF_Import!A$5:A$500)-ROW(GF_Import!A$5)+1)/(GF_Import!A$5:A$500=$B$2),7)+ROW(GF_Import!A$5)-1,ROW(GF_Import!A$5:A$500)-ROW(GF_Import!A$5)+1+ROW(GF_Import!A$5)-1,0)),"") | D15: =IFERROR(INDEX(GF_Import!D:D,MATCH(AGGREGATE(15,6,(ROW(GF_Import!A$5:A$500)-ROW(GF_Import!A$5)+1)/(GF_Import!A$5:A$500=$B$2),7)+ROW(GF_Import!A$5)-1,ROW(GF_Import!A$5:A$500)-ROW(GF_Import!A$5)+1+ROW(GF_Import!A$5)-1,0)),"") | E15: =IFERROR(INDEX(GF_Import!E:E,MATCH(AGGREGATE(15,6,(ROW(GF_Import!A$5:A$500)-ROW(GF_Import!A$5)+1)/(GF_Import!A$5:A$500=$B$2),7)+ROW(GF_Import!A$5)-1,ROW(GF_Import!A$5:A$500)-ROW(GF_Import!A$5)+1+ROW(GF_Import!A$5)-1,0)),"") | F15: =IFERROR(INDEX(GF_Import!F:F,MATCH(AGGREGATE(15,6,(ROW(GF_Import!A$5:A$500)-ROW(GF_Import!A$5)+1)/(GF_Import!A$5:A$500=$B$2),7)+ROW(GF_Import!A$5)-1,ROW(GF_Import!A$5:A$500)-ROW(GF_Import!A$5)+1+ROW(GF_Import!A$5)-1,0)),"") | G15: =IFERROR(INDEX(GF_Import!G:G,MATCH(AGGREGATE(15,6,(ROW(GF_Import!A$5:A$500)-ROW(GF_Import!A$5)+1)/(GF_Import!A$5:A$500=$B$2),7)+ROW(GF_Import!A$5)-1,ROW(GF_Import!A$5:A$500)-ROW(GF_Import!A$5)+1+ROW(GF_Import!A$5)-1,0)),"") | H15: =IF(F15="","",IFERROR(AVERAGEIF(GF_Import!A:A,$B$2,GF_Import!F:F),"")) | I15: =IF(OR(F15="",F14=""),"",IFERROR((F15-F14)/F14,""))
A16: 8 | B16: =IFERROR(INDEX(GF_Import!B:B,MATCH(AGGREGATE(15,6,(ROW(GF_Import!A$5:A$500)-ROW(GF_Import!A$5)+1)/(GF_Import!A$5:A$500=$B$2),8)+ROW(GF_Import!A$5)-1,ROW(GF_Import!A$5:A$500)-ROW(GF_Import!A$5)+1+ROW(GF_Import!A$5)-1,0)),"") | C16: =IFERROR(INDEX(GF_Import!C:C,MATCH(AGGREGATE(15,6,(ROW(GF_Import!A$5:A$500)-ROW(GF_Import!A$5)+1)/(GF_Import!A$5:A$500=$B$2),8)+ROW(GF_Import!A$5)-1,ROW(GF_Import!A$5:A$500)-ROW(GF_Import!A$5)+1+ROW(GF_Import!A$5)-1,0)),"") | D16: =IFERROR(INDEX(GF_Import!D:D,MATCH(AGGREGATE(15,6,(ROW(GF_Import!A$5:A$500)-ROW(GF_Import!A$5)+1)/(GF_Import!A$5:A$500=$B$2),8)+ROW(GF_Import!A$5)-1,ROW(GF_Import!A$5:A$500)-ROW(GF_Import!A$5)+1+ROW(GF_Import!A$5)-1,0)),"") | E16: =IFERROR(INDEX(GF_Import!E:E,MATCH(AGGREGATE(15,6,(ROW(GF_Import!A$5:A$500)-ROW(GF_Import!A$5)+1)/(GF_Import!A$5:A$500=$B$2),8)+ROW(GF_Import!A$5)-1,ROW(GF_Import!A$5:A$500)-ROW(GF_Import!A$5)+1+ROW(GF_Import!A$5)-1,0)),"") | F16: =IFERROR(INDEX(GF_Import!F:F,MATCH(AGGREGATE(15,6,(ROW(GF_Import!A$5:A$500)-ROW(GF_Import!A$5)+1)/(GF_Import!A$5:A$500=$B$2),8)+ROW(GF_Import!A$5)-1,ROW(GF_Import!A$5:A$500)-ROW(GF_Import!A$5)+1+ROW(GF_Import!A$5)-1,0)),"") | G16: =IFERROR(INDEX(GF_Import!G:G,MATCH(AGGREGATE(15,6,(ROW(GF_Import!A$5:A$500)-ROW(GF_Import!A$5)+1)/(GF_Import!A$5:A$500=$B$2),8)+ROW(GF_Import!A$5)-1,ROW(GF_Import!A$5:A$500)-ROW(GF_Import!A$5)+1+ROW(GF_Import!A$5)-1,0)),"") | H16: =IF(F16="","",IFERROR(AVERAGEIF(GF_Import!A:A,$B$2,GF_Import!F:F),"")) | I16: =IF(OR(F16="",F15=""),"",IFERROR((F16-F15)/F15,""))
A17: 9 | B17: =IFERROR(INDEX(GF_Import!B:B,MATCH(AGGREGATE(15,6,(ROW(GF_Import!A$5:A$500)-ROW(GF_Import!A$5)+1)/(GF_Import!A$5:A$500=$B$2),9)+ROW(GF_Import!A$5)-1,ROW(GF_Import!A$5:A$500)-ROW(GF_Import!A$5)+1+ROW(GF_Import!A$5)-1,0)),"") | C17: =IFERROR(INDEX(GF_Import!C:C,MATCH(AGGREGATE(15,6,(ROW(GF_Import!A$5:A$500)-ROW(GF_Import!A$5)+1)/(GF_Import!A$5:A$500=$B$2),9)+ROW(GF_Import!A$5)-1,ROW(GF_Import!A$5:A$500)-ROW(GF_Import!A$5)+1+ROW(GF_Import!A$5)-1,0)),"") | D17: =IFERROR(INDEX(GF_Import!D:D,MATCH(AGGREGATE(15,6,(ROW(GF_Import!A$5:A$500)-ROW(GF_Import!A$5)+1)/(GF_Import!A$5:A$500=$B$2),9)+ROW(GF_Import!A$5)-1,ROW(GF_Import!A$5:A$500)-ROW(GF_Import!A$5)+1+ROW(GF_Import!A$5)-1,0)),"") | E17: =IFERROR(INDEX(GF_Import!E:E,MATCH(AGGREGATE(15,6,(ROW(GF_Import!A$5:A$500)-ROW(GF_Import!A$5)+1)/(GF_Import!A$5:A$500=$B$2),9)+ROW(GF_Import!A$5)-1,ROW(GF_Import!A$5:A$500)-ROW(GF_Import!A$5)+1+ROW(GF_Import!A$5)-1,0)),"") | F17: =IFERROR(INDEX(GF_Import!F:F,MATCH(AGGREGATE(15,6,(ROW(GF_Import!A$5:A$500)-ROW(GF_Import!A$5)+1)/(GF_Import!A$5:A$500=$B$2),9)+ROW(GF_Import!A$5)-1,ROW(GF_Import!A$5:A$500)-ROW(GF_Import!A$5)+1+ROW(GF_Import!A$5)-1,0)),"") | G17: =IFERROR(INDEX(GF_Import!G:G,MATCH(AGGREGATE(15,6,(ROW(GF_Import!A$5:A$500)-ROW(GF_Import!A$5)+1)/(GF_Import!A$5:A$500=$B$2),9)+ROW(GF_Import!A$5)-1,ROW(GF_Import!A$5:A$500)-ROW(GF_Import!A$5)+1+ROW(GF_Import!A$5)-1,0)),"") | H17: =IF(F17="","",IFERROR(AVERAGEIF(GF_Import!A:A,$B$2,GF_Import!F:F),"")) | I17: =IF(OR(F17="",F16=""),"",IFERROR((F17-F16)/F16,""))
A18: 10 | B18: =IFERROR(INDEX(GF_Import!B:B,MATCH(AGGREGATE(15,6,(ROW(GF_Import!A$5:A$500)-ROW(GF_Import!A$5)+1)/(GF_Import!A$5:A$500=$B$2),10)+ROW(GF_Import!A$5)-1,ROW(GF_Import!A$5:A$500)-ROW(GF_Import!A$5)+1+ROW(GF_Import!A$5)-1,0)),"") | C18: =IFERROR(INDEX(GF_Import!C:C,MATCH(AGGREGATE(15,6,(ROW(GF_Import!A$5:A$500)-ROW(GF_Import!A$5)+1)/(GF_Import!A$5:A$500=$B$2),10)+ROW(GF_Import!A$5)-1,ROW(GF_Import!A$5:A$500)-ROW(GF_Import!A$5)+1+ROW(GF_Import!A$5)-1,0)),"") | D18: =IFERROR(INDEX(GF_Import!D:D,MATCH(AGGREGATE(15,6,(ROW(GF_Import!A$5:A$500)-ROW(GF_Import!A$5)+1)/(GF_Import!A$5:A$500=$B$2),10)+ROW(GF_Import!A$5)-1,ROW(GF_Import!A$5:A$500)-ROW(GF_Import!A$5)+1+ROW(GF_Import!A$5)-1,0)),"") | E18: =IFERROR(INDEX(GF_Import!E:E,MATCH(AGGREGATE(15,6,(ROW(GF_Import!A$5:A$500)-ROW(GF_Import!A$5)+1)/(GF_Import!A$5:A$500=$B$2),10)+ROW(GF_Import!A$5)-1,ROW(GF_Import!A$5:A$500)-ROW(GF_Import!A$5)+1+ROW(GF_Import!A$5)-1,0)),"") | F18: =IFERROR(INDEX(GF_Import!F:F,MATCH(AGGREGATE(15,6,(ROW(GF_Import!A$5:A$500)-ROW(GF_Import!A$5)+1)/(GF_Import!A$5:A$500=$B$2),10)+ROW(GF_Import!A$5)-1,ROW(GF_Import!A$5:A$500)-ROW(GF_Import!A$5)+1+ROW(GF_Import!A$5)-1,0)),"") | G18: =IFERROR(INDEX(GF_Import!G:G,MATCH(AGGREGATE(15,6,(ROW(GF_Import!A$5:A$500)-ROW(GF_Import!A$5)+1)/(GF_Import!A$5:A$500=$B$2),10)+ROW(GF_Import!A$5)-1,ROW(GF_Import!A$5:A$500)-ROW(GF_Import!A$5)+1+ROW(GF_Import!A$5)-1,0)),"") | H18: =IF(F18="","",IFERROR(AVERAGEIF(GF_Import!A:A,$B$2,GF_Import!F:F),"")) | I18: =IF(OR(F18="",F17=""),"",IFERROR((F18-F17)/F17,""))
A19: 11 | B19: =IFERROR(INDEX(GF_Import!B:B,MATCH(AGGREGATE(15,6,(ROW(GF_Import!A$5:A$500)-ROW(GF_Import!A$5)+1)/(GF_Import!A$5:A$500=$B$2),11)+ROW(GF_Import!A$5)-1,ROW(GF_Import!A$5:A$500)-ROW(GF_Import!A$5)+1+ROW(GF_Import!A$5)-1,0)),"") | C19: =IFERROR(INDEX(GF_Import!C:C,MATCH(AGGREGATE(15,6,(ROW(GF_Import!A$5:A$500)-ROW(GF_Import!A$5)+1)/(GF_Import!A$5:A$500=$B$2),11)+ROW(GF_Import!A$5)-1,ROW(GF_Import!A$5:A$500)-ROW(GF_Import!A$5)+1+ROW(GF_Import!A$5)-1,0)),"") | D19: =IFERROR(INDEX(GF_Import!D:D,MATCH(AGGREGATE(15,6,(ROW(GF_Import!A$5:A$500)-ROW(GF_Import!A$5)+1)/(GF_Import!A$5:A$500=$B$2),11)+ROW(GF_Import!A$5)-1,ROW(GF_Import!A$5:A$500)-ROW(GF_Import!A$5)+1+ROW(GF_Import!A$5)-1,0)),"") | E19: =IFERROR(INDEX(GF_Import!E:E,MATCH(AGGREGATE(15,6,(ROW(GF_Import!A$5:A$500)-ROW(GF_Import!A$5)+1)/(GF_Import!A$5:A$500=$B$2),11)+ROW(GF_Import!A$5)-1,ROW(GF_Import!A$5:A$500)-ROW(GF_Import!A$5)+1+ROW(GF_Import!A$5)-1,0)),"") | F19: =IFERROR(INDEX(GF_Import!F:F,MATCH(AGGREGATE(15,6,(ROW(GF_Import!A$5:A$500)-ROW(GF_Import!A$5)+1)/(GF_Import!A$5:A$500=$B$2),11)+ROW(GF_Import!A$5)-1,ROW(GF_Import!A$5:A$500)-ROW(GF_Import!A$5)+1+ROW(GF_Import!A$5)-1,0)),"") | G19: =IFERROR(INDEX(GF_Import!G:G,MATCH(AGGREGATE(15,6,(ROW(GF_Import!A$5:A$500)-ROW(GF_Import!A$5)+1)/(GF_Import!A$5:A$500=$B$2),11)+ROW(GF_Import!A$5)-1,ROW(GF_Import!A$5:A$500)-ROW(GF_Import!A$5)+1+ROW(GF_Import!A$5)-1,0)),"") | H19: =IF(F19="","",IFERROR(AVERAGEIF(GF_Import!A:A,$B$2,GF_Import!F:F),"")) | I19: =IF(OR(F19="",F18=""),"",IFERROR((F19-F18)/F18,""))
A20: 12 | B20: =IFERROR(INDEX(GF_Import!B:B,MATCH(AGGREGATE(15,6,(ROW(GF_Import!A$5:A$500)-ROW(GF_Import!A$5)+1)/(GF_Import!A$5:A$500=$B$2),12)+ROW(GF_Import!A$5)-1,ROW(GF_Import!A$5:A$500)-ROW(GF_Import!A$5)+1+ROW(GF_Import!A$5)-1,0)),"") | C20: =IFERROR(INDEX(GF_Import!C:C,MATCH(AGGREGATE(15,6,(ROW(GF_Import!A$5:A$500)-ROW(GF_Import!A$5)+1)/(GF_Import!A$5:A$500=$B$2),12)+ROW(GF_Import!A$5)-1,ROW(GF_Import!A$5:A$500)-ROW(GF_Import!A$5)+1+ROW(GF_Import!A$5)-1,0)),"") | D20: =IFERROR(INDEX(GF_Import!D:D,MATCH(AGGREGATE(15,6,(ROW(GF_Import!A$5:A$500)-ROW(GF_Import!A$5)+1)/(GF_Import!A$5:A$500=$B$2),12)+ROW(GF_Import!A$5)-1,ROW(GF_Import!A$5:A$500)-ROW(GF_Import!A$5)+1+ROW(GF_Import!A$5)-1,0)),"") | E20: =IFERROR(INDEX(GF_Import!E:E,MATCH(AGGREGATE(15,6,(ROW(GF_Import!A$5:A$500)-ROW(GF_Import!A$5)+1)/(GF_Import!A$5:A$500=$B$2),12)+ROW(GF_Import!A$5)-1,ROW(GF_Import!A$5:A$500)-ROW(GF_Import!A$5)+1+ROW(GF_Import!A$5)-1,0)),"") | F20: =IFERROR(INDEX(GF_Import!F:F,MATCH(AGGREGATE(15,6,(ROW(GF_Import!A$5:A$500)-ROW(GF_Import!A$5)+1)/(GF_Import!A$5:A$500=$B$2),12)+ROW(GF_Import!A$5)-1,ROW(GF_Import!A$5:A$500)-ROW(GF_Import!A$5)+1+ROW(GF_Import!A$5)-1,0)),"") | G20: =IFERROR(INDEX(GF_Import!G:G,MATCH(AGGREGATE(15,6,(ROW(GF_Import!A$5:A$500)-ROW(GF_Import!A$5)+1)/(GF_Import!A$5:A$500=$B$2),12)+ROW(GF_Import!A$5)-1,ROW(GF_Import!A$5:A$500)-ROW(GF_Import!A$5)+1+ROW(GF_Import!A$5)-1,0)),"") | H20: =IF(F20="","",IFERROR(AVERAGEIF(GF_Import!A:A,$B$2,GF_Import!F:F),"")) | I20: =IF(OR(F20="",F19=""),"",IFERROR((F20-F19)/F19,""))
A21: 13 | B21: =IFERROR(INDEX(GF_Import!B:B,MATCH(AGGREGATE(15,6,(ROW(GF_Import!A$5:A$500)-ROW(GF_Import!A$5)+1)/(GF_Import!A$5:A$500=$B$2),13)+ROW(GF_Import!A$5)-1,ROW(GF_Import!A$5:A$500)-ROW(GF_Import!A$5)+1+ROW(GF_Import!A$5)-1,0)),"") | C21: =IFERROR(INDEX(GF_Import!C:C,MATCH(AGGREGATE(15,6,(ROW(GF_Import!A$5:A$500)-ROW(GF_Import!A$5)+1)/(GF_Import!A$5:A$500=$B$2),13)+ROW(GF_Import!A$5)-1,ROW(GF_Import!A$5:A$500)-ROW(GF_Import!A$5)+1+ROW(GF_Import!A$5)-1,0)),"") | D21: =IFERROR(INDEX(GF_Import!D:D,MATCH(AGGREGATE(15,6,(ROW(GF_Import!A$5:A$500)-ROW(GF_Import!A$5)+1)/(GF_Import!A$5:A$500=$B$2),13)+ROW(GF_Import!A$5)-1,ROW(GF_Import!A$5:A$500)-ROW(GF_Import!A$5)+1+ROW(GF_Import!A$5)-1,0)),"") | E21: =IFERROR(INDEX(GF_Import!E:E,MATCH(AGGREGATE(15,6,(ROW(GF_Import!A$5:A$500)-ROW(GF_Import!A$5)+1)/(GF_Import!A$5:A$500=$B$2),13)+ROW(GF_Import!A$5)-1,ROW(GF_Import!A$5:A$500)-ROW(GF_Import!A$5)+1+ROW(GF_Import!A$5)-1,0)),"") | F21: =IFERROR(INDEX(GF_Import!F:F,MATCH(AGGREGATE(15,6,(ROW(GF_Import!A$5:A$500)-ROW(GF_Import!A$5)+1)/(GF_Import!A$5:A$500=$B$2),13)+ROW(GF_Import!A$5)-1,ROW(GF_Import!A$5:A$500)-ROW(GF_Import!A$5)+1+ROW(GF_Import!A$5)-1,0)),"") | G21: =IFERROR(INDEX(GF_Import!G:G,MATCH(AGGREGATE(15,6,(ROW(GF_Import!A$5:A$500)-ROW(GF_Import!A$5)+1)/(GF_Import!A$5:A$500=$B$2),13)+ROW(GF_Import!A$5)-1,ROW(GF_Import!A$5:A$500)-ROW(GF_Import!A$5)+1+ROW(GF_Import!A$5)-1,0)),"") | H21: =IF(F21="","",IFERROR(AVERAGEIF(GF_Import!A:A,$B$2,GF_Import!F:F),"")) | I21: =IF(OR(F21="",F20=""),"",IFERROR((F21-F20)/F20,""))
A22: 14 | B22: =IFERROR(INDEX(GF_Import!B:B,MATCH(AGGREGATE(15,6,(ROW(GF_Import!A$5:A$500)-ROW(GF_Import!A$5)+1)/(GF_Import!A$5:A$500=$B$2),14)+ROW(GF_Import!A$5)-1,ROW(GF_Import!A$5:A$500)-ROW(GF_Import!A$5)+1+ROW(GF_Import!A$5)-1,0)),"") | C22: =IFERROR(INDEX(GF_Import!C:C,MATCH(AGGREGATE(15,6,(ROW(GF_Import!A$5:A$500)-ROW(GF_Import!A$5)+1)/(GF_Import!A$5:A$500=$B$2),14)+ROW(GF_Import!A$5)-1,ROW(GF_Import!A$5:A$500)-ROW(GF_Import!A$5)+1+ROW(GF_Import!A$5)-1,0)),"") | D22: =IFERROR(INDEX(GF_Import!D:D,MATCH(AGGREGATE(15,6,(ROW(GF_Import!A$5:A$500)-ROW(GF_Import!A$5)+1)/(GF_Import!A$5:A$500=$B$2),14)+ROW(GF_Import!A$5)-1,ROW(GF_Import!A$5:A$500)-ROW(GF_Import!A$5)+1+ROW(GF_Import!A$5)-1,0)),"") | E22: =IFERROR(INDEX(GF_Import!E:E,MATCH(AGGREGATE(15,6,(ROW(GF_Import!A$5:A$500)-ROW(GF_Import!A$5)+1)/(GF_Import!A$5:A$500=$B$2),14)+ROW(GF_Import!A$5)-1,ROW(GF_Import!A$5:A$500)-ROW(GF_Import!A$5)+1+ROW(GF_Import!A$5)-1,0)),"") | F22: =IFERROR(INDEX(GF_Import!F:F,MATCH(AGGREGATE(15,6,(ROW(GF_Import!A$5:A$500)-ROW(GF_Import!A$5)+1)/(GF_Import!A$5:A$500=$B$2),14)+ROW(GF_Import!A$5)-1,ROW(GF_Import!A$5:A$500)-ROW(GF_Import!A$5)+1+ROW(GF_Import!A$5)-1,0)),"") | G22: =IFERROR(INDEX(GF_Import!G:G,MATCH(AGGREGATE(15,6,(ROW(GF_Import!A$5:A$500)-ROW(GF_Import!A$5)+1)/(GF_Import!A$5:A$500=$B$2),14)+ROW(GF_Import!A$5)-1,ROW(GF_Import!A$5:A$500)-ROW(GF_Import!A$5)+1+ROW(GF_Import!A$5)-1,0)),"") | H22: =IF(F22="","",IFERROR(AVERAGEIF(GF_Import!A:A,$B$2,GF_Import!F:F),"")) | I22: =IF(OR(F22="",F21=""),"",IFERROR((F22-F21)/F21,""))
A23: 15 | B23: =IFERROR(INDEX(GF_Import!B:B,MATCH(AGGREGATE(15,6,(ROW(GF_Import!A$5:A$500)-ROW(GF_Import!A$5)+1)/(GF_Import!A$5:A$500=$B$2),15)+ROW(GF_Import!A$5)-1,ROW(GF_Import!A$5:A$500)-ROW(GF_Import!A$5)+1+ROW(GF_Import!A$5)-1,0)),"") | C23: =IFERROR(INDEX(GF_Import!C:C,MATCH(AGGREGATE(15,6,(ROW(GF_Import!A$5:A$500)-ROW(GF_Import!A$5)+1)/(GF_Import!A$5:A$500=$B$2),15)+ROW(GF_Import!A$5)-1,ROW(GF_Import!A$5:A$500)-ROW(GF_Import!A$5)+1+ROW(GF_Import!A$5)-1,0)),"") | D23: =IFERROR(INDEX(GF_Import!D:D,MATCH(AGGREGATE(15,6,(ROW(GF_Import!A$5:A$500)-ROW(GF_Import!A$5)+1)/(GF_Import!A$5:A$500=$B$2),15)+ROW(GF_Import!A$5)-1,ROW(GF_Import!A$5:A$500)-ROW(GF_Import!A$5)+1+ROW(GF_Import!A$5)-1,0)),"") | E23: =IFERROR(INDEX(GF_Import!E:E,MATCH(AGGREGATE(15,6,(ROW(GF_Import!A$5:A$500)-ROW(GF_Import!A$5)+1)/(GF_Import!A$5:A$500=$B$2),15)+ROW(GF_Import!A$5)-1,ROW(GF_Import!A$5:A$500)-ROW(GF_Import!A$5)+1+ROW(GF_Import!A$5)-1,0)),"") | F23: =IFERROR(INDEX(GF_Import!F:F,MATCH(AGGREGATE(15,6,(ROW(GF_Import!A$5:A$500)-ROW(GF_Import!A$5)+1)/(GF_Import!A$5:A$500=$B$2),15)+ROW(GF_Import!A$5)-1,ROW(GF_Import!A$5:A$500)-ROW(GF_Import!A$5)+1+ROW(GF_Import!A$5)-1,0)),"") | G23: =IFERROR(INDEX(GF_Import!G:G,MATCH(AGGREGATE(15,6,(ROW(GF_Import!A$5:A$500)-ROW(GF_Import!A$5)+1)/(GF_Import!A$5:A$500=$B$2),15)+ROW(GF_Import!A$5)-1,ROW(GF_Import!A$5:A$500)-ROW(GF_Import!A$5)+1+ROW(GF_Import!A$5)-1,0)),"") | H23: =IF(F23="","",IFERROR(AVERAGEIF(GF_Import!A:A,$B$2,GF_Import!F:F),"")) | I23: =IF(OR(F23="",F22=""),"",IFERROR((F23-F22)/F22,""))
A24: 16 | B24: =IFERROR(INDEX(GF_Import!B:B,MATCH(AGGREGATE(15,6,(ROW(GF_Import!A$5:A$500)-ROW(GF_Import!A$5)+1)/(GF_Import!A$5:A$500=$B$2),16)+ROW(GF_Import!A$5)-1,ROW(GF_Import!A$5:A$500)-ROW(GF_Import!A$5)+1+ROW(GF_Import!A$5)-1,0)),"") | C24: =IFERROR(INDEX(GF_Import!C:C,MATCH(AGGREGATE(15,6,(ROW(GF_Import!A$5:A$500)-ROW(GF_Import!A$5)+1)/(GF_Import!A$5:A$500=$B$2),16)+ROW(GF_Import!A$5)-1,ROW(GF_Import!A$5:A$500)-ROW(GF_Import!A$5)+1+ROW(GF_Import!A$5)-1,0)),"") | D24: =IFERROR(INDEX(GF_Import!D:D,MATCH(AGGREGATE(15,6,(ROW(GF_Import!A$5:A$500)-ROW(GF_Import!A$5)+1)/(GF_Import!A$5:A$500=$B$2),16)+ROW(GF_Import!A$5)-1,ROW(GF_Import!A$5:A$500)-ROW(GF_Import!A$5)+1+ROW(GF_Import!A$5)-1,0)),"") | E24: =IFERROR(INDEX(GF_Import!E:E,MATCH(AGGREGATE(15,6,(ROW(GF_Import!A$5:A$500)-ROW(GF_Import!A$5)+1)/(GF_Import!A$5:A$500=$B$2),16)+ROW(GF_Import!A$5)-1,ROW(GF_Import!A$5:A$500)-ROW(GF_Import!A$5)+1+ROW(GF_Import!A$5)-1,0)),"") | F24: =IFERROR(INDEX(GF_Import!F:F,MATCH(AGGREGATE(15,6,(ROW(GF_Import!A$5:A$500)-ROW(GF_Import!A$5)+1)/(GF_Import!A$5:A$500=$B$2),16)+ROW(GF_Import!A$5)-1,ROW(GF_Import!A$5:A$500)-ROW(GF_Import!A$5)+1+ROW(GF_Import!A$5)-1,0)),"") | G24: =IFERROR(INDEX(GF_Import!G:G,MATCH(AGGREGATE(15,6,(ROW(GF_Import!A$5:A$500)-ROW(GF_Import!A$5)+1)/(GF_Import!A$5:A$500=$B$2),16)+ROW(GF_Import!A$5)-1,ROW(GF_Import!A$5:A$500)-ROW(GF_Import!A$5)+1+ROW(GF_Import!A$5)-1,0)),"") | H24: =IF(F24="","",IFERROR(AVERAGEIF(GF_Import!A:A,$B$2,GF_Import!F:F),"")) | I24: =IF(OR(F24="",F23=""),"",IFERROR((F24-F23)/F23,""))
A25: 17 | B25: =IFERROR(INDEX(GF_Import!B:B,MATCH(AGGREGATE(15,6,(ROW(GF_Import!A$5:A$500)-ROW(GF_Import!A$5)+1)/(GF_Import!A$5:A$500=$B$2),17)+ROW(GF_Import!A$5)-1,ROW(GF_Import!A$5:A$500)-ROW(GF_Import!A$5)+1+ROW(GF_Import!A$5)-1,0)),"") | C25: =IFERROR(INDEX(GF_Import!C:C,MATCH(AGGREGATE(15,6,(ROW(GF_Import!A$5:A$500)-ROW(GF_Import!A$5)+1)/(GF_Import!A$5:A$500=$B$2),17)+ROW(GF_Import!A$5)-1,ROW(GF_Import!A$5:A$500)-ROW(GF_Import!A$5)+1+ROW(GF_Import!A$5)-1,0)),"") | D25: =IFERROR(INDEX(GF_Import!D:D,MATCH(AGGREGATE(15,6,(ROW(GF_Import!A$5:A$500)-ROW(GF_Import!A$5)+1)/(GF_Import!A$5:A$500=$B$2),17)+ROW(GF_Import!A$5)-1,ROW(GF_Import!A$5:A$500)-ROW(GF_Import!A$5)+1+ROW(GF_Import!A$5)-1,0)),"") | E25: =IFERROR(INDEX(GF_Import!E:E,MATCH(AGGREGATE(15,6,(ROW(GF_Import!A$5:A$500)-ROW(GF_Import!A$5)+1)/(GF_Import!A$5:A$500=$B$2),17)+ROW(GF_Import!A$5)-1,ROW(GF_Import!A$5:A$500)-ROW(GF_Import!A$5)+1+ROW(GF_Import!A$5)-1,0)),"") | F25: =IFERROR(INDEX(GF_Import!F:F,MATCH(AGGREGATE(15,6,(ROW(GF_Import!A$5:A$500)-ROW(GF_Import!A$5)+1)/(GF_Import!A$5:A$500=$B$2),17)+ROW(GF_Import!A$5)-1,ROW(GF_Import!A$5:A$500)-ROW(GF_Import!A$5)+1+ROW(GF_Import!A$5)-1,0)),"") | G25: =IFERROR(INDEX(GF_Import!G:G,MATCH(AGGREGATE(15,6,(ROW(GF_Import!A$5:A$500)-ROW(GF_Import!A$5)+1)/(GF_Import!A$5:A$500=$B$2),17)+ROW(GF_Import!A$5)-1,ROW(GF_Import!A$5:A$500)-ROW(GF_Import!A$5)+1+ROW(GF_Import!A$5)-1,0)),"") | H25: =IF(F25="","",IFERROR(AVERAGEIF(GF_Import!A:A,$B$2,GF_Import!F:F),"")) | I25: =IF(OR(F25="",F24=""),"",IFERROR((F25-F24)/F24,""))
A26: 18 | B26: =IFERROR(INDEX(GF_Import!B:B,MATCH(AGGREGATE(15,6,(ROW(GF_Import!A$5:A$500)-ROW(GF_Import!A$5)+1)/(GF_Import!A$5:A$500=$B$2),18)+ROW(GF_Import!A$5)-1,ROW(GF_Import!A$5:A$500)-ROW(GF_Import!A$5)+1+ROW(GF_Import!A$5)-1,0)),"") | C26: =IFERROR(INDEX(GF_Import!C:C,MATCH(AGGREGATE(15,6,(ROW(GF_Import!A$5:A$500)-ROW(GF_Import!A$5)+1)/(GF_Import!A$5:A$500=$B$2),18)+ROW(GF_Import!A$5)-1,ROW(GF_Import!A$5:A$500)-ROW(GF_Import!A$5)+1+ROW(GF_Import!A$5)-1,0)),"") | D26: =IFERROR(INDEX(GF_Import!D:D,MATCH(AGGREGATE(15,6,(ROW(GF_Import!A$5:A$500)-ROW(GF_Import!A$5)+1)/(GF_Import!A$5:A$500=$B$2),18)+ROW(GF_Import!A$5)-1,ROW(GF_Import!A$5:A$500)-ROW(GF_Import!A$5)+1+ROW(GF_Import!A$5)-1,0)),"") | E26: =IFERROR(INDEX(GF_Import!E:E,MATCH(AGGREGATE(15,6,(ROW(GF_Import!A$5:A$500)-ROW(GF_Import!A$5)+1)/(GF_Import!A$5:A$500=$B$2),18)+ROW(GF_Import!A$5)-1,ROW(GF_Import!A$5:A$500)-ROW(GF_Import!A$5)+1+ROW(GF_Import!A$5)-1,0)),"") | F26: =IFERROR(INDEX(GF_Import!F:F,MATCH(AGGREGATE(15,6,(ROW(GF_Import!A$5:A$500)-ROW(GF_Import!A$5)+1)/(GF_Import!A$5:A$500=$B$2),18)+ROW(GF_Import!A$5)-1,ROW(GF_Import!A$5:A$500)-ROW(GF_Import!A$5)+1+ROW(GF_Import!A$5)-1,0)),"") | G26: =IFERROR(INDEX(GF_Import!G:G,MATCH(AGGREGATE(15,6,(ROW(GF_Import!A$5:A$500)-ROW(GF_Import!A$5)+1)/(GF_Import!A$5:A$500=$B$2),18)+ROW(GF_Import!A$5)-1,ROW(GF_Import!A$5:A$500)-ROW(GF_Import!A$5)+1+ROW(GF_Import!A$5)-1,0)),"") | H26: =IF(F26="","",IFERROR(AVERAGEIF(GF_Import!A:A,$B$2,GF_Import!F:F),"")) | I26: =IF(OR(F26="",F25=""),"",IFERROR((F26-F25)/F25,""))
A27: 19 | B27: =IFERROR(INDEX(GF_Import!B:B,MATCH(AGGREGATE(15,6,(ROW(GF_Import!A$5:A$500)-ROW(GF_Import!A$5)+1)/(GF_Import!A$5:A$500=$B$2),19)+ROW(GF_Import!A$5)-1,ROW(GF_Import!A$5:A$500)-ROW(GF_Import!A$5)+1+ROW(GF_Import!A$5)-1,0)),"") | C27: =IFERROR(INDEX(GF_Import!C:C,MATCH(AGGREGATE(15,6,(ROW(GF_Import!A$5:A$500)-ROW(GF_Import!A$5)+1)/(GF_Import!A$5:A$500=$B$2),19)+ROW(GF_Import!A$5)-1,ROW(GF_Import!A$5:A$500)-ROW(GF_Import!A$5)+1+ROW(GF_Import!A$5)-1,0)),"") | D27: =IFERROR(INDEX(GF_Import!D:D,MATCH(AGGREGATE(15,6,(ROW(GF_Import!A$5:A$500)-ROW(GF_Import!A$5)+1)/(GF_Import!A$5:A$500=$B$2),19)+ROW(GF_Import!A$5)-1,ROW(GF_Import!A$5:A$500)-ROW(GF_Import!A$5)+1+ROW(GF_Import!A$5)-1,0)),"") | E27: =IFERROR(INDEX(GF_Import!E:E,MATCH(AGGREGATE(15,6,(ROW(GF_Import!A$5:A$500)-ROW(GF_Import!A$5)+1)/(GF_Import!A$5:A$500=$B$2),19)+ROW(GF_Import!A$5)-1,ROW(GF_Import!A$5:A$500)-ROW(GF_Import!A$5)+1+ROW(GF_Import!A$5)-1,0)),"") | F27: =IFERROR(INDEX(GF_Import!F:F,MATCH(AGGREGATE(15,6,(ROW(GF_Import!A$5:A$500)-ROW(GF_Import!A$5)+1)/(GF_Import!A$5:A$500=$B$2),19)+ROW(GF_Import!A$5)-1,ROW(GF_Import!A$5:A$500)-ROW(GF_Import!A$5)+1+ROW(GF_Import!A$5)-1,0)),"") | G27: =IFERROR(INDEX(GF_Import!G:G,MATCH(AGGREGATE(15,6,(ROW(GF_Import!A$5:A$500)-ROW(GF_Import!A$5)+1)/(GF_Import!A$5:A$500=$B$2),19)+ROW(GF_Import!A$5)-1,ROW(GF_Import!A$5:A$500)-ROW(GF_Import!A$5)+1+ROW(GF_Import!A$5)-1,0)),"") | H27: =IF(F27="","",IFERROR(AVERAGEIF(GF_Import!A:A,$B$2,GF_Import!F:F),"")) | I27: =IF(OR(F27="",F26=""),"",IFERROR((F27-F26)/F26,""))
A28: 20 | B28: =IFERROR(INDEX(GF_Import!B:B,MATCH(AGGREGATE(15,6,(ROW(GF_Import!A$5:A$500)-ROW(GF_Import!A$5)+1)/(GF_Import!A$5:A$500=$B$2),20)+ROW(GF_Import!A$5)-1,ROW(GF_Import!A$5:A$500)-ROW(GF_Import!A$5)+1+ROW(GF_Import!A$5)-1,0)),"") | C28: =IFERROR(INDEX(GF_Import!C:C,MATCH(AGGREGATE(15,6,(ROW(GF_Import!A$5:A$500)-ROW(GF_Import!A$5)+1)/(GF_Import!A$5:A$500=$B$2),20)+ROW(GF_Import!A$5)-1,ROW(GF_Import!A$5:A$500)-ROW(GF_Import!A$5)+1+ROW(GF_Import!A$5)-1,0)),"") | D28: =IFERROR(INDEX(GF_Import!D:D,MATCH(AGGREGATE(15,6,(ROW(GF_Import!A$5:A$500)-ROW(GF_Import!A$5)+1)/(GF_Import!A$5:A$500=$B$2),20)+ROW(GF_Import!A$5)-1,ROW(GF_Import!A$5:A$500)-ROW(GF_Import!A$5)+1+ROW(GF_Import!A$5)-1,0)),"") | E28: =IFERROR(INDEX(GF_Import!E:E,MATCH(AGGREGATE(15,6,(ROW(GF_Import!A$5:A$500)-ROW(GF_Import!A$5)+1)/(GF_Import!A$5:A$500=$B$2),20)+ROW(GF_Import!A$5)-1,ROW(GF_Import!A$5:A$500)-ROW(GF_Import!A$5)+1+ROW(GF_Import!A$5)-1,0)),"") | F28: =IFERROR(INDEX(GF_Import!F:F,MATCH(AGGREGATE(15,6,(ROW(GF_Import!A$5:A$500)-ROW(GF_Import!A$5)+1)/(GF_Import!A$5:A$500=$B$2),20)+ROW(GF_Import!A$5)-1,ROW(GF_Import!A$5:A$500)-ROW(GF_Import!A$5)+1+ROW(GF_Import!A$5)-1,0)),"") | G28: =IFERROR(INDEX(GF_Import!G:G,MATCH(AGGREGATE(15,6,(ROW(GF_Import!A$5:A$500)-ROW(GF_Import!A$5)+1)/(GF_Import!A$5:A$500=$B$2),20)+ROW(GF_Import!A$5)-1,ROW(GF_Import!A$5:A$500)-ROW(GF_Import!A$5)+1+ROW(GF_Import!A$5)-1,0)),"") | H28: =IF(F28="","",IFERROR(AVERAGEIF(GF_Import!A:A,$B$2,GF_Import!F:F),"")) | I28: =IF(OR(F28="",F27=""),"",IFERROR((F28-F27)/F27,""))

Sheet PE_PBV_Band
A1: 💰 ANALISIS VALUASI — PE BAND & PBV BAND
B2: INPUT DATA | G2: PE BAND (input historis — lihat RTI/BMAD) | L2: PBV BAND (input historis) | AE2: UPSIDE / DOWNSIDE KE SETIAP BAND LEVEL
A3: KODE | B3: Harga Close | C3: EPS TTM | D3: BVPS | E3: PE Min | F3: PE -1SD | G3: PE Median | H3: PE +1SD | I3: PE Max | J3: PBV Min | K3: PBV -1SD | L3: PBV Median | M3: PBV +1SD | N3: PBV Max | O3: PE Curr | P3: PBV Curr | Q3: Impl PE Min | R3: Impl PE -1SD | S3: Impl PE Med | T3: Impl PE +1SD | U3: Impl PE Max | V3: Impl PBV Min | W3: Impl PBV -1SD | X3: Impl PBV Med | Y3: Impl PBV +1SD | Z3: Impl PBV Max | AA3: PE %ile | AB3: PBV %ile | AC3: PE Label | AD3: PBV Label | AE3: Ke PE Min | AF3: Ke PE -1SD | AG3: Ke PE Med | AH3: Ke PE +1SD | AI3: Ke PE Max | AJ3: Ke PBV Min | AK3: Ke PBV -1SD | AL3: Ke PBV Med | AM3: Ke PBV +1SD | AN3: Ke PBV Max
A4: ↑ INPUT | C4: PE Curr | D4: PBV Curr | E4: Impl Min | F4: Impl -1SD | G4: Impl Med | H4: Impl +1SD | I4: Impl Max | J4: Impl Min | K4: Impl -1SD | L4: Impl Med | M4: Impl +1SD | N4: Impl Max | O4: PE %ile | P4: PBV %ile | Q4: PE Label | R4: PBV Label
A5: BBCA | B5: 6275 | C5: 471.04 | D5: 2108.889 | E5: 10.3 | F5: 13.9 | G5: 16.3 | H5: 17.6 | I5: 19.6 | J5: 2.3 | K5: 3.1 | L5: 3.63 | M5: 3.94 | N5: 4.38 | O5: =IFERROR(B5/C5,"-") | P5: =IFERROR(B5/D5,"-") | Q5: =IFERROR(E5*C5,"-") | R5: =IFERROR(F5*C5,"-") | S5: =IFERROR(G5*C5,"-") | T5: =IFERROR(H5*C5,"-") | U5: =IFERROR(I5*C5,"-") | V5: =IFERROR(J5*D5,"-") | W5: =IFERROR(K5*D5,"-") | X5: =IFERROR(L5*D5,"-") | Y5: =IFERROR(M5*D5,"-") | Z5: =IFERROR(N5*D5,"-") | AA5: =IFERROR((O5-E5)/(I5-E5)*100,"-") | AB5: =IFERROR((P5-J5)/(N5-J5)*100,"-") | AC5: =IFERROR(IF(AA5<15,"🟢 Deep Under",IF(AA5<35,"🟡 Undervalued",IF(AA5<65,"⚪ Fair Value",IF(AA5<85,"🟠 Overvalued","🔴 Deep Over")))),"N/A") | AD5: =IFERROR(IF(AB5<15,"🟢 Deep Under",IF(AB5<35,"🟡 Undervalued",IF(AB5<65,"⚪ Fair Value",IF(AB5<85,"🟠 Overvalued","🔴 Deep Over")))),"N/A") | AE5: =IFERROR((Q5-B5)/B5,"-") | AF5: =IFERROR((R5-B5)/B5,"-") | AG5: =IFERROR((S5-B5)/B5,"-") | AH5: =IFERROR((T5-B5)/B5,"-") | AI5: =IFERROR((U5-B5)/B5,"-") | AJ5: =IFERROR((V5-B5)/B5,"-") | AK5: =IFERROR((W5-B5)/B5,"-") | AL5: =IFERROR((X5-B5)/B5,"-") | AM5: =IFERROR((Y5-B5)/B5,"-") | AN5: =IFERROR((Z5-B5)/B5,"-")
A6: BBRI | B6: 2990 | C6: 389.03 | D6: 2246.081 | E6: 6.7 | F6: 8.2 | G6: 8.9 | H6: 9.5 | I6: 10.4 | J6: 1.15 | K6: 1.42 | L6: 1.54 | M6: 1.64 | N6: 1.79 | O6: =IFERROR(B6/C6,"-") | P6: =IFERROR(B6/D6,"-") | Q6: =IFERROR(E6*C6,"-") | R6: =IFERROR(F6*C6,"-") | S6: =IFERROR(G6*C6,"-") | T6: =IFERROR(H6*C6,"-") | U6: =IFERROR(I6*C6,"-") | V6: =IFERROR(J6*D6,"-") | W6: =IFERROR(K6*D6,"-") | X6: =IFERROR(L6*D6,"-") | Y6: =IFERROR(M6*D6,"-") | Z6: =IFERROR(N6*D6,"-") | AA6: =IFERROR((O6-E6)/(I6-E6)*100,"-") | AB6: =IFERROR((P6-J6)/(N6-J6)*100,"-") | AC6: =IFERROR(IF(AA6<15,"🟢 Deep Under",IF(AA6<35,"🟡 Undervalued",IF(AA6<65,"⚪ Fair Value",IF(AA6<85,"🟠 Overvalued","🔴 Deep Over")))),"N/A") | AD6: =IFERROR(IF(AB6<15,"🟢 Deep Under",IF(AB6<35,"🟡 Undervalued",IF(AB6<65,"⚪ Fair Value",IF(AB6<85,"🟠 Overvalued","🔴 Deep Over")))),"N/A") | AE6: =IFERROR((Q6-B6)/B6,"-") | AF6: =IFERROR((R6-B6)/B6,"-") | AG6: =IFERROR((S6-B6)/B6,"-") | AH6: =IFERROR((T6-B6)/B6,"-") | AI6: =IFERROR((U6-B6)/B6,"-") | AJ6: =IFERROR((V6-B6)/B6,"-") | AK6: =IFERROR((W6-B6)/B6,"-") | AL6: =IFERROR((X6-B6)/B6,"-") | AM6: =IFERROR((Y6-B6)/B6,"-") | AN6: =IFERROR((Z6-B6)/B6,"-")
A7: TLKM | B7: 2930 | C7: 164.45 | D7: 1360.33 | E7: 14.3 | F7: 17.1 | G7: 18.9 | H7: 21.1 | I7: 24 | J7: 1.73 | K7: 2.06 | L7: 2.28 | M7: 2.55 | N7: 2.9 | O7: =IFERROR(B7/C7,"-") | P7: =IFERROR(B7/D7,"-") | Q7: =IFERROR(E7*C7,"-") | R7: =IFERROR(F7*C7,"-") | S7: =IFERROR(G7*C7,"-") | T7: =IFERROR(H7*C7,"-") | U7: =IFERROR(I7*C7,"-") | V7: =IFERROR(J7*D7,"-") | W7: =IFERROR(K7*D7,"-") | X7: =IFERROR(L7*D7,"-") | Y7: =IFERROR(M7*D7,"-") | Z7: =IFERROR(N7*D7,"-") | AA7: =IFERROR((O7-E7)/(I7-E7)*100,"-") | AB7: =IFERROR((P7-J7)/(N7-J7)*100,"-") | AC7: =IFERROR(IF(AA7<15,"🟢 Deep Under",IF(AA7<35,"🟡 Undervalued",IF(AA7<65,"⚪ Fair Value",IF(AA7<85,"🟠 Overvalued","🔴 Deep Over")))),"N/A") | AD7: =IFERROR(IF(AB7<15,"🟢 Deep Under",IF(AB7<35,"🟡 Undervalued",IF(AB7<65,"⚪ Fair Value",IF(AB7<85,"🟠 Overvalued","🔴 Deep Over")))),"N/A") | AE7: =IFERROR((Q7-B7)/B7,"-") | AF7: =IFERROR((R7-B7)/B7,"-") | AG7: =IFERROR((S7-B7)/B7,"-") | AH7: =IFERROR((T7-B7)/B7,"-") | AI7: =IFERROR((U7-B7)/B7,"-") | AJ7: =IFERROR((V7-B7)/B7,"-") | AK7: =IFERROR((W7-B7)/B7,"-") | AL7: =IFERROR((X7-B7)/B7,"-") | AM7: =IFERROR((Y7-B7)/B7,"-") | AN7: =IFERROR((Z7-B7)/B7,"-")
A8: DEWA | B8: 370 | C8: 111.94 | D8: 193.602 | E8: 1.4 | F8: 1.9 | G8: 3.2 | H8: 4.9 | I8: 7.3 | J8: 0.79 | K8: 1.1 | L8: 1.83 | M8: 2.82 | N8: 4.21 | O8: =IFERROR(B8/C8,"-") | P8: =IFERROR(B8/D8,"-") | Q8: =IFERROR(E8*C8,"-") | R8: =IFERROR(F8*C8,"-") | S8: =IFERROR(G8*C8,"-") | T8: =IFERROR(H8*C8,"-") | U8: =IFERROR(I8*C8,"-") | V8: =IFERROR(J8*D8,"-") | W8: =IFERROR(K8*D8,"-") | X8: =IFERROR(L8*D8,"-") | Y8: =IFERROR(M8*D8,"-") | Z8: =IFERROR(N8*D8,"-") | AA8: =IFERROR((O8-E8)/(I8-E8)*100,"-") | AB8: =IFERROR((P8-J8)/(N8-J8)*100,"-") | AC8: =IFERROR(IF(AA8<15,"🟢 Deep Under",IF(AA8<35,"🟡 Undervalued",IF(AA8<65,"⚪ Fair Value",IF(AA8<85,"🟠 Overvalued","🔴 Deep Over")))),"N/A") | AD8: =IFERROR(IF(AB8<15,"🟢 Deep Under",IF(AB8<35,"🟡 Undervalued",IF(AB8<65,"⚪ Fair Value",IF(AB8<85,"🟠 Overvalued","🔴 Deep Over")))),"N/A") | AE8: =IFERROR((Q8-B8)/B8,"-") | AF8: =IFERROR((R8-B8)/B8,"-") | AG8: =IFERROR((S8-B8)/B8,"-") | AH8: =IFERROR((T8-B8)/B8,"-") | AI8: =IFERROR((U8-B8)/B8,"-") | AJ8: =IFERROR((V8-B8)/B8,"-") | AK8: =IFERROR((W8-B8)/B8,"-") | AL8: =IFERROR((X8-B8)/B8,"-") | AM8: =IFERROR((Y8-B8)/B8,"-") | AN8: =IFERROR((Z8-B8)/B8,"-")
A12: PE Band Chart Data (BBCA)
A13: Level | B13: Implied Price | C13: Harga Saat Ini
A14: Min | B14: =Q5 | C14: =B5
A15: -1SD | B15: =R5 | C15: =B5
A16: Median | B16: =S5 | C16: =B5
A17: +1SD | B17: =T5 | C17: =B5
A18: Max | B18: =U5 | C18: =B5

Sheet Consensus_EPS
A1: 📋 CONSENSUS ESTIMATE & ANALYST RATING
B2: ANALYST RATING | E2: TARGET PRICE | H2: EPS ESTIMATE | K2: REVENUE (Rp Miliar) | N2: CONSENSUS OUTPUT | P2: SKOR & LABEL
A3: KODE | B3: Buy | C3: Hold | D3: Sell | E3: TP Low | F3: TP Mean | G3: TP High | H3: EPS FY0 | I3: EPS FY1 | J3: EPS Grwth | K3: Rev FY0 | L3: Rev FY1 | M3: Rev Grwth | N3: Next Earnings | O3: Catalyst | P3: Consensus Score | Q3: Consensus Label | R3: Upside ke Mean
A4: BBCA | B4: 23 | C4: 1 | D4: 0 | E4: 5500 | F4: 8888.542 | G4: 10900 | H4: 486.09213 | I4: 529.8603 | J4: =IFERROR((I4-H4)/ABS(H4),"-") | K4: 118350 | L4: 128400 | M4: =IFERROR((L4-K4)/K4,"-") | N4: 2026-07-22 | P4: =IFERROR((B4*100+C4*50)/(B4+C4+D4),"-") | Q4: =IFERROR(IF(P4>=70,"🟢 BULLISH",IF(P4>=40,"🟡 NEUTRAL","🔴 BEARISH")),"N/A") | R4: =IFERROR((F4-VLOOKUP(A4,PE_PBV_Band!A:B,2,0))/VLOOKUP(A4,PE_PBV_Band!A:B,2,0),"-")
A5: BBRI | B5: 17 | C5: 3 | D5: 2 | E5: 2740 | F5: 4054.524 | G5: 4900 | H5: 392.047 | I5: 424.89175 | J5: =IFERROR((I5-H5)/ABS(H5),"-") | K5: 232310 | L5: 243340 | M5: =IFERROR((L5-K5)/K5,"-") | N5: 2026-07-29 | P5: =IFERROR((B5*100+C5*50)/(B5+C5+D5),"-") | Q5: =IFERROR(IF(P5>=70,"🟢 BULLISH",IF(P5>=40,"🟡 NEUTRAL","🔴 BEARISH")),"N/A") | R5: =IFERROR((F5-VLOOKUP(A5,PE_PBV_Band!A:B,2,0))/VLOOKUP(A5,PE_PBV_Band!A:B,2,0),"-")
A6: TLKM | B6: 15 | C6: 7 | D6: 0 | E6: 3000 | F6: 3657.0454 | G6: 4150 | H6: 212.41917 | I6: 236.69254 | J6: =IFERROR((I6-H6)/ABS(H6),"-") | K6: 153740 | L6: 155110 | M6: =IFERROR((L6-K6)/K6,"-") | N6: 2026-07-30 | P6: =IFERROR((B6*100+C6*50)/(B6+C6+D6),"-") | Q6: =IFERROR(IF(P6>=70,"🟢 BULLISH",IF(P6>=40,"🟡 NEUTRAL","🔴 BEARISH")),"N/A") | R6: =IFERROR((F6-VLOOKUP(A6,PE_PBV_Band!A:B,2,0))/VLOOKUP(A6,PE_PBV_Band!A:B,2,0),"-")
A7: DEWA | B7: 4 | C7: 0 | D7: 0 | E7: 707.8 | F7: 951.10626 | G7: 1397.905 | H7: 0.001 | I7: 0.0015 | J7: =IFERROR((I7-H7)/ABS(H7),"-") | K7: 0 | L7: 0 | M7: =IFERROR((L7-K7)/K7,"-") | P7: =IFERROR((B7*100+C7*50)/(B7+C7+D7),"-") | Q7: =IFERROR(IF(P7>=70,"🟢 BULLISH",IF(P7>=40,"🟡 NEUTRAL","🔴 BEARISH")),"N/A") | R7: =IFERROR((F7-VLOOKUP(A7,PE_PBV_Band!A:B,2,0))/VLOOKUP(A7,PE_PBV_Band!A:B,2,0),"-")
A11: Pie Data (BBCA) | D11: TP Range
A12: Buy | B12: =B4 | D12: Low | E12: =E4
A13: Hold | B13: =C4 | D13: Mean | E13: =F4
A14: Sell | B14: =D4 | D14: High | E14: =G4
D15: Harga Saat Ini | E15: =VLOOKUP(A4,PE_PBV_Band!A:B,2,0)

Sheet Brief_Sync
A1: 🔄 BRIEF SYNC — Output untuk Scalping Brief Generator App
A2: Copy nilai dari kolom NILAI ke input field yang sesuai di Scalping Brief Generator App
A4: ▶ BBCA — SCALPING BRIEF DATA
A5: MODULE | B5: FIELD | C5: NILAI | D5: SATUAN | E5: CATATAN | F5: STATUS
A6: Kandidat | B6: Kode Saham | C6: =PE_PBV_Band!A5 | D6: – | E6: Kode IDX | F6: =IF(C6="","⚠️ Kosong","✅ Siap")
A7: Kandidat | B7: Harga Close | C7: =PE_PBV_Band!B5 | D7: Rp | E7: Dari GF_Import | F7: =IF(C7="","⚠️ Kosong","✅ Siap")
A8: Valuasi | B8: PE Saat Ini | C8: =PE_PBV_Band!O5 | D8: x | E8: EPS TTM | F8: =IF(C8="","⚠️ Kosong","✅ Siap")
A9: Valuasi | B9: PBV Saat Ini | C9: =PE_PBV_Band!P5 | D9: x | E9: BVPS | F9: =IF(C9="","⚠️ Kosong","✅ Siap")
A10: Valuasi | B10: PE Implied Med | C10: =PE_PBV_Band!S5 | D10: Rp | E10: PE Median Band | F10: =IF(C10="","⚠️ Kosong","✅ Siap")
A11: Valuasi | B11: Upside PE Med | C11: =PE_PBV_Band!AG5 | D11: % | E11: Ke PE Median | F11: =IF(C11="","⚠️ Kosong","✅ Siap")
A12: Valuasi | B12: Label Valuasi | C12: =PE_PBV_Band!AC5 | D12: – | E12: Auto dari percentile | F12: =IF(C12="","⚠️ Kosong","✅ Siap")
A13: Consensus | B13: Rating | C13: =Consensus_EPS!Q4 | D13: – | E13: Bullish/Neutral/Bear | F13: =IF(C13="","⚠️ Kosong","✅ Siap")
A14: Consensus | B14: Cons Score | C14: =Consensus_EPS!P4 | D14: /100 | E14: Weighted avg | F14: =IF(C14="","⚠️ Kosong","✅ Siap")
A15: Consensus | B15: TP Mean | C15: =Consensus_EPS!F4 | D15: Rp | E15: Mean target analis | F15: =IF(C15="","⚠️ Kosong","✅ Siap")
A16: Consensus | B16: Upside TP | C16: =Consensus_EPS!R4 | D16: % | E16: Vs harga saat ini | F16: =IF(C16="","⚠️ Kosong","✅ Siap")
A17: Consensus | B17: EPS FY0 | C17: =Consensus_EPS!H4 | D17: Rp | E17: TTM / FY aktual | F17: =IF(C17="","⚠️ Kosong","✅ Siap")
A18: Consensus | B18: EPS FY1 Est | C18: =Consensus_EPS!I4 | D18: Rp | E18: Estimasi analis | F18: =IF(C18="","⚠️ Kosong","✅ Siap")
A19: Consensus | B19: EPS Growth | C19: =Consensus_EPS!J4 | D19: % | E19: YoY | F19: =IF(C19="","⚠️ Kosong","✅ Siap")
A20: Consensus | B20: Next Earnings | C20: =Consensus_EPS!N4 | D20: – | E20: Tanggal LK berikutnya | F20: =IF(C20="","⚠️ Kosong","✅ Siap")
A22: ▶ BBRI — SCALPING BRIEF DATA
A23: MODULE | B23: FIELD | C23: NILAI | D23: SATUAN | E23: CATATAN | F23: STATUS
A24: Kandidat | B24: Kode Saham | C24: =PE_PBV_Band!A6 | D24: – | E24: Kode IDX | F24: =IF(C24="","⚠️ Kosong","✅ Siap")
A25: Kandidat | B25: Harga Close | C25: =PE_PBV_Band!B6 | D25: Rp | E25: Dari GF_Import | F25: =IF(C25="","⚠️ Kosong","✅ Siap")
A26: Valuasi | B26: PE Saat Ini | C26: =PE_PBV_Band!O6 | D26: x | E26: EPS TTM | F26: =IF(C26="","⚠️ Kosong","✅ Siap")
A27: Valuasi | B27: PBV Saat Ini | C27: =PE_PBV_Band!P6 | D27: x | E27: BVPS | F27: =IF(C27="","⚠️ Kosong","✅ Siap")
A28: Valuasi | B28: PE Implied Med | C28: =PE_PBV_Band!S6 | D28: Rp | E28: PE Median Band | F28: =IF(C28="","⚠️ Kosong","✅ Siap")
A29: Valuasi | B29: Upside PE Med | C29: =PE_PBV_Band!AG6 | D29: % | E29: Ke PE Median | F29: =IF(C29="","⚠️ Kosong","✅ Siap")
A30: Valuasi | B30: Label Valuasi | C30: =PE_PBV_Band!AC6 | D30: – | E30: Auto dari percentile | F30: =IF(C30="","⚠️ Kosong","✅ Siap")
A31: Consensus | B31: Rating | C31: =Consensus_EPS!Q5 | D31: – | E31: Bullish/Neutral/Bear | F31: =IF(C31="","⚠️ Kosong","✅ Siap")
A32: Consensus | B32: Cons Score | C32: =Consensus_EPS!P5 | D32: /100 | E32: Weighted avg | F32: =IF(C32="","⚠️ Kosong","✅ Siap")
A33: Consensus | B33: TP Mean | C33: =Consensus_EPS!F5 | D33: Rp | E33: Mean target analis | F33: =IF(C33="","⚠️ Kosong","✅ Siap")
A34: Consensus | B34: Upside TP | C34: =Consensus_EPS!R5 | D34: % | E34: Vs harga saat ini | F34: =IF(C34="","⚠️ Kosong","✅ Siap")
A35: Consensus | B35: EPS FY0 | C35: =Consensus_EPS!H5 | D35: Rp | E35: TTM / FY aktual | F35: =IF(C35="","⚠️ Kosong","✅ Siap")
A36: Consensus | B36: EPS FY1 Est | C36: =Consensus_EPS!I5 | D36: Rp | E36: Estimasi analis | F36: =IF(C36="","⚠️ Kosong","✅ Siap")
A37: Consensus | B37: EPS Growth | C37: =Consensus_EPS!J5 | D37: % | E37: YoY | F37: =IF(C37="","⚠️ Kosong","✅ Siap")
A38: Consensus | B38: Next Earnings | C38: =Consensus_EPS!N5 | D38: – | E38: Tanggal LK berikutnya | F38: =IF(C38="","⚠️ Kosong","✅ Siap")
A40: ▶ TLKM — SCALPING BRIEF DATA
A41: MODULE | B41: FIELD | C41: NILAI | D41: SATUAN | E41: CATATAN | F41: STATUS
A42: Kandidat | B42: Kode Saham | C42: =PE_PBV_Band!A7 | D42: – | E42: Kode IDX | F42: =IF(C42="","⚠️ Kosong","✅ Siap")
A43: Kandidat | B43: Harga Close | C43: =PE_PBV_Band!B7 | D43: Rp | E43: Dari GF_Import | F43: =IF(C43="","⚠️ Kosong","✅ Siap")
...
